# CH11. 예외처리



LBYL

EAFP





## panic!

Rust에는 `try ... except` 가 없다.








## Result enum

```rust,ignore
enum Result<T, E> {
    Ok(T),
    Err(E),
}

```



### ?

If the result is not `Some` , instantly terminates the function and returns `None`

unwrap

unwrap_or



```python
import os


def fail():
    raise Exception


def get_content():
    filepath = os.path.join(os.path.pardir, "test.txt")
    with open(filepath, "r") as f:
        return f.read()


class CustomError(Exception):
    pass


if __name__ == '__main__':

    # fail() # -> this will stop the program

    try:
        with open("hello.txt", "r") as file:
            file.read()
    except FileNotFoundError as exc:
        print(exc)
    except:
        print("Unexpected error")

    content = ""
    try:
        content = get_content()
    except:
        raise CustomError
    print(content)

```







```rust,ignore
use std::fmt;
use std::fs::File;
use std::io::{Error, ErrorKind, Read};
use std::path::Path;

#[allow(dead_code)]
fn fail() {
    panic!()
}

fn get_content() -> Result<String, Error> {
    let mut content = String::new();
    let filepath = Path::new(std::env::current_dir().unwrap().parent().unwrap()).join("test.txt");
    File::open(filepath)?.read_to_string(&mut content)?;
    Ok(content)
}

#[derive(Debug, Clone)]
struct CustomError;

impl fmt::Display for CustomError {
    fn fmt(&self, f: &mut fmt::Formatter) -> fmt::Result {
        write!(f, "")
    }
}

fn main() {
    // fail(); // -> this will stop the program

    let file = File::open("hello.txt");
    match file {
        Ok(file) => println!("{:?}", file),
        Err(error) => match error.kind() {
            ErrorKind::NotFound => println!("{:?}", error),
            _ => println!("Unexpected error"),
        },
    }

    let content = match get_content() {
        Ok(c) => c,
        Err(_) => {
            panic!("{}", CustomError);
        }
    };
    println!("{}", content);
}

```


